Workbook

Sheet config
A1: customer_id | B1: driver_id | C1: alt_drop_off_id | D1: Điểm Pick-up | E1: Điểm Drop-off thay thế | F1: Driver | G1: bot_token | H1: chat_id | I1: shift_start | J1: shift_end | K1: smart_driver_id
A2: d4fa76f4-b95a-11f0-be92-506b8d982279 | B2: =IFNA(VLOOKUP(F2,Driver!A:C,2,false),"") -> 8094d712-0f78-11f0-b96d-506b8d982279 | C2: =IFNA(VLOOKUP(E2,'Location Table'!A:C,2,false),"") | D2: 10000 - D10 - CMT8 - Test Julie | F2: Nguyễn Thành Long | G2: =IFNA(VLOOKUP(F2,Driver!A:D,4,false),"") | H2: =IFNA(VLOOKUP(F2,Driver!A:C,3,false),"") | I2: 0.29166667 | J2: 0.66666667
A3: =IFNA(VLOOKUP(D3,'Location Table'!A:C,2,false),"") -> 7fefc6d4-4539-11ed-94b3-506b8dbc8dfb | B3: =IFNA(VLOOKUP(F3,Driver!A:C,2,false),"") -> 7898dd6c-816d-11f0-9f34-506b8d982279 | C3: =IFNA(VLOOKUP(E3,'Location Table'!A:C,2,false),"") | D3: 10232 - BHoa - VTSau - PKĐK Tâm An | F3: F - P - DC101785 Nguyễn Quốc Cường | G3: =IFNA(VLOOKUP(F3,Driver!A:D,4,false),"") -> 1980698793628880414:XXMGIAegigeHesHcPUQpIcnMCwhigvPUATFrPyRHiqIZqTwmvWiXbUzfDhivxPcl | H3: =IFNA(VLOOKUP(F3,Driver!A:C,3,false),"") -> 011b70c8f4801dde4491 | I3: 0.29166667 | J3: 0.66666667
A4: =IFNA(VLOOKUP(D4,'Location Table'!A:C,2,false),"") -> 84d326dc-4543-11ed-a50a-506b8dbc8dfb | B4: =IFNA(VLOOKUP(F4,Driver!A:C,2,false),"") -> 7898dd6c-816d-11f0-9f34-506b8d982279 | C4: =IFNA(VLOOKUP(E4,'Location Table'!A:C,2,false),"") | D4: 10281 - BHoa - DVTron - Kien Clinic | F4: F - P - DC101785 Nguyễn Quốc Cường | G4: =IFNA(VLOOKUP(F4,Driver!A:D,4,false),"") -> 1980698793628880414:XXMGIAegigeHesHcPUQpIcnMCwhigvPUATFrPyRHiqIZqTwmvWiXbUzfDhivxPcl | H4: =IFNA(VLOOKUP(F4,Driver!A:C,3,false),"") -> 011b70c8f4801dde4491 | I4: 0.29166667 | J4: 0.66666667
A5: =IFNA(VLOOKUP(D5,'Location Table'!A:C,2,false),"") -> 6e14d1d4-11de-11ef-9e30-506b8d9879b5 | B5: =IFNA(VLOOKUP(F5,Driver!A:C,2,false),"") -> 7898dd6c-816d-11f0-9f34-506b8d982279 | C5: =IFNA(VLOOKUP(E5,'Location Table'!A:C,2,false),"") | D5: 10304 - BHoa - 30/4 - Nguyễn Trần Tố Nữ Yến Nhi | F5: F - P - DC101785 Nguyễn Quốc Cường | G5: =IFNA(VLOOKUP(F5,Driver!A:D,4,false),"") -> 1980698793628880414:XXMGIAegigeHesHcPUQpIcnMCwhigvPUATFrPyRHiqIZqTwmvWiXbUzfDhivxPcl | H5: =IFNA(VLOOKUP(F5,Driver!A:C,3,false),"") -> 011b70c8f4801dde4491 | I5: 0.29166667 | J5: 0.66666667
A6: =IFNA(VLOOKUP(D6,'Location Table'!A:C,2,false),"") -> 61af27cc-8aad-11ee-b551-506b8d9879b5 | B6: =IFNA(VLOOKUP(F6,Driver!A:C,2,false),"") -> 7898dd6c-816d-11f0-9f34-506b8d982279 | C6: =IFNA(VLOOKUP(E6,'Location Table'!A:C,2,false),"") | D6: 10323 - BHoa - DKhoi - Phạm Thị Thu Thảo | F6: F - P - DC101785 Nguyễn Quốc Cường | G6: =IFNA(VLOOKUP(F6,Driver!A:D,4,false),"") -> 1980698793628880414:XXMGIAegigeHesHcPUQpIcnMCwhigvPUATFrPyRHiqIZqTwmvWiXbUzfDhivxPcl | H6: =IFNA(VLOOKUP(F6,Driver!A:C,3,false),"") -> 011b70c8f4801dde4491 | I6: 0.29166667 | J6: 0.66666667
A7: =IFNA(VLOOKUP(D7,'Location Table'!A:C,2,false),"") -> 41126efc-4349-11ef-8430-506b8d9879b5 | B7: =IFNA(VLOOKUP(F7,Driver!A:C,2,false),"") -> 7898dd6c-816d-11f0-9f34-506b8d982279 | C7: =IFNA(VLOOKUP(E7,'Location Table'!A:C,2,false),"") | D7: 10405 - BHoa - VTSau - Trần Viết Hợi | F7: F - P - DC101785 Nguyễn Quốc Cường | G7: =IFNA(VLOOKUP(F7,Driver!A:D,4,false),"") -> 1980698793628880414:XXMGIAegigeHesHcPUQpIcnMCwhigvPUATFrPyRHiqIZqTwmvWiXbUzfDhivxPcl | H7: =IFNA(VLOOKUP(F7,Driver!A:C,3,false),"") -> 011b70c8f4801dde4491 | I7: 0.29166667 | J7: 0.66666667
A8: =IFNA(VLOOKUP(D8,'Location Table'!A:C,2,false),"") -> 4f07dccc-9ce9-11f0-99fb-506b8d982279 | B8: =IFNA(VLOOKUP(F8,Driver!A:C,2,false),"") -> 7898dd6c-816d-11f0-9f34-506b8d982279 | C8: =IFNA(VLOOKUP(E8,'Location Table'!A:C,2,false),"") | D8: 10877 - BHoa - NAQuoc - Nguyễn Thị Anh Ngân | F8: F - P - DC101785 Nguyễn Quốc Cường | G8: =IFNA(VLOOKUP(F8,Driver!A:D,4,false),"") -> 1980698793628880414:XXMGIAegigeHesHcPUQpIcnMCwhigvPUATFrPyRHiqIZqTwmvWiXbUzfDhivxPcl | H8: =IFNA(VLOOKUP(F8,Driver!A:C,3,false),"") -> 011b70c8f4801dde4491 | I8: 0.29166667 | J8: 0.66666667
A9: =IFNA(VLOOKUP(D9,'Location Table'!A:C,2,false),"") -> f036056c-8a92-11ee-b9a1-506b8d9879b5 | B9: =IFNA(VLOOKUP(F9,Driver!A:C,2,false),"") -> 7898dd6c-816d-11f0-9f34-506b8d982279 | C9: =IFNA(VLOOKUP(E9,'Location Table'!A:C,2,false),"") | D9: 11628 - BHoa - DKhoi - Nguyễn Thị Hoàng Yến | F9: F - P - DC101785 Nguyễn Quốc Cường | G9: =IFNA(VLOOKUP(F9,Driver!A:D,4,false),"") -> 1980698793628880414:XXMGIAegigeHesHcPUQpIcnMCwhigvPUATFrPyRHiqIZqTwmvWiXbUzfDhivxPcl | H9: =IFNA(VLOOKUP(F9,Driver!A:C,3,false),"") -> 011b70c8f4801dde4491 | I9: 0.29166667 | J9: 0.66666667
A10: =IFNA(VLOOKUP(D10,'Location Table'!A:C,2,false),"") -> 230eb4e2-a57d-11ef-a7db-506b8d9879b5 | B10: =IFNA(VLOOKUP(F10,Driver!A:C,2,false),"") -> 7898dd6c-816d-11f0-9f34-506b8d982279 | C10: =IFNA(VLOOKUP(E10,'Location Table'!A:C,2,false),"") | D10: 11704 - BHoa - DKhoi - Đồng Khắc Sơn | F10: F - P - DC101785 Nguyễn Quốc Cường | G10: =IFNA(VLOOKUP(F10,Driver!A:D,4,false),"") -> 1980698793628880414:XXMGIAegigeHesHcPUQpIcnMCwhigvPUATFrPyRHiqIZqTwmvWiXbUzfDhivxPcl | H10: =IFNA(VLOOKUP(F10,Driver!A:C,3,false),"") -> 011b70c8f4801dde4491 | I10: 0.29166667 | J10: 0.66666667
A11: =IFNA(VLOOKUP(D11,'Location Table'!A:C,2,false),"") -> f5c156fc-11b7-11ee-a03b-506b8dbc8dfb | B11: =IFNA(VLOOKUP(F11,Driver!A:C,2,false),"") -> 7898dd6c-816d-11f0-9f34-506b8d982279 | C11: =IFNA(VLOOKUP(E11,'Location Table'!A:C,2,false),"") | D11: 11704 - BHoa - LBinh - Đồng Khắc Sơn | F11: F - P - DC101785 Nguyễn Quốc Cường | G11: =IFNA(VLOOKUP(F11,Driver!A:D,4,false),"") -> 1980698793628880414:XXMGIAegigeHesHcPUQpIcnMCwhigvPUATFrPyRHiqIZqTwmvWiXbUzfDhivxPcl | H11: =IFNA(VLOOKUP(F11,Driver!A:C,3,false),"") -> 011b70c8f4801dde4491 | I11: 0.29166667 | J11: 0.66666667
A12: =IFNA(VLOOKUP(D12,'Location Table'!A:C,2,false),"") -> 3999a980-0f35-11ef-b000-506b8d9879b5 | B12: =IFNA(VLOOKUP(F12,Driver!A:C,2,false),"") -> 7898dd6c-816d-11f0-9f34-506b8d982279 | C12: =IFNA(VLOOKUP(E12,'Location Table'!A:C,2,false),"") | D12: 11752 - BHoa - F3 - Nguyễn Kim Sơn | F12: F - P - DC101785 Nguyễn Quốc Cường | G12: =IFNA(VLOOKUP(F12,Driver!A:D,4,false),"") -> 1980698793628880414:XXMGIAegigeHesHcPUQpIcnMCwhigvPUATFrPyRHiqIZqTwmvWiXbUzfDhivxPcl | H12: =IFNA(VLOOKUP(F12,Driver!A:C,3,false),"") -> 011b70c8f4801dde4491 | I12: 0.29166667 | J12: 0.66666667
A13: =IFNA(VLOOKUP(D13,'Location Table'!A:C,2,false),"") -> d6fca2e0-513f-11ee-8a83-506b8d9879b5 | B13: =IFNA(VLOOKUP(F13,Driver!A:C,2,false),"") -> 7898dd6c-816d-11f0-9f34-506b8d982279 | C13: =IFNA(VLOOKUP(E13,'Location Table'!A:C,2,false),"") | D13: 11888 - BHoa - DVTron - Quách Thị Thu Hiền | F13: F - P - DC101785 Nguyễn Quốc Cường | G13: =IFNA(VLOOKUP(F13,Driver!A:D,4,false),"") -> 1980698793628880414:XXMGIAegigeHesHcPUQpIcnMCwhigvPUATFrPyRHiqIZqTwmvWiXbUzfDhivxPcl | H13: =IFNA(VLOOKUP(F13,Driver!A:C,3,false),"") -> 011b70c8f4801dde4491 | I13: 0.29166667 | J13: 0.66666667
A14: =IFNA(VLOOKUP(D14,'Location Table'!A:C,2,false),"") -> 8741aed2-0d86-11ee-bea3-506b8dbc8dfb | B14: =IFNA(VLOOKUP(F14,Driver!A:C,2,false),"") -> 7898dd6c-816d-11f0-9f34-506b8d982279 | C14: =IFNA(VLOOKUP(E14,'Location Table'!A:C,2,false),"") | D14: 11957 - BHoa - BHNghia - BS. Phan Văn Trọng | F14: F - P - DC101785 Nguyễn Quốc Cường | G14: =IFNA(VLOOKUP(F14,Driver!A:D,4,false),"") -> 1980698793628880414:XXMGIAegigeHesHcPUQpIcnMCwhigvPUATFrPyRHiqIZqTwmvWiXbUzfDhivxPcl | H14: =IFNA(VLOOKUP(F14,Driver!A:C,3,false),"") -> 011b70c8f4801dde4491 | I14: 0.29166667 | J14: 0.66666667
... A299: =IFNA(VLOOKUP(D299,'Location Table'!A:C,2,false),"") -> 68682bea-755d-11ef-9d29-506b8d9879b5 | B299: =IFNA(VLOOKUP(F299,Driver!A:C,2,false),"") -> e3970cec-503e-11f1-9378-fa163ee8d8ac | C299: =IFNA(VLOOKUP(E299,'Location Table'!A:C,2,false),"") | D299: 21362 - BThanh - NXi - PS315 Nguyễn Xí | F299: F - C - DC100017 Khưu Tấn Tài | G299: =IFNA(VLOOKUP(F299,Driver!A:D,4,false),"") | H299: =IFNA(VLOOKUP(F299,Driver!A:C,3,false),"") | I299: 0.29166667 | J299: 0.79166667
A300: =IFNA(VLOOKUP(D300,'Location Table'!A:C,2,false),"") -> 323821e8-59e6-11ef-bc31-506b8d9879b5 | B300: =IFNA(VLOOKUP(F300,Driver!A:C,2,false),"") -> 9ba6de4c-37d0-11ed-90bb-506b8dbc8dfb | C300: =IFNA(VLOOKUP(E300,'Location Table'!A:C,2,false),"") | D300: 21362 - CChi - QL22 - PS315 QL22 | F300: F - P - DC101161 Trần Nguyễn Thanh Duy | G300: =IFNA(VLOOKUP(F300,Driver!A:D,4,false),"") -> 1980698793628880414:XXMGIAegigeHesHcPUQpIcnMCwhigvPUATFrPyRHiqIZqTwmvWiXbUzfDhivxPcl | H300: =IFNA(VLOOKUP(F300,Driver!A:C,3,false),"") -> d0ce770b76499f17c658 | I300: 0.25 | J300: 0.64583333 | K300: 9ba6de4c-37d0-11ed-90bb-506b8dbc8dfb,987568fa-37c7-11ed-aac2-506b8dbc8dfb
A301: =IFNA(VLOOKUP(D301,'Location Table'!A:C,2,false),"") -> fd168f54-e9ef-11f0-a0fb-506b8d982279 | B301: =IFNA(VLOOKUP(F301,Driver!A:C,2,false),"") -> 9ba6de4c-37d0-11ed-90bb-506b8dbc8dfb | C301: =IFNA(VLOOKUP(E301,'Location Table'!A:C,2,false),"") | D301: 21362 - CChi - TL8 - PS315 61-63 Tỉnh Lộ 8 | F301: F - P - DC101161 Trần Nguyễn Thanh Duy | G301: =IFNA(VLOOKUP(F301,Driver!A:D,4,false),"") -> 1980698793628880414:XXMGIAegigeHesHcPUQpIcnMCwhigvPUATFrPyRHiqIZqTwmvWiXbUzfDhivxPcl | H301: =IFNA(VLOOKUP(F301,Driver!A:C,3,false),"") -> d0ce770b76499f17c658 | I301: 0.25 | J301: 0.64583333 | K301: 9ba6de4c-37d0-11ed-90bb-506b8dbc8dfb,987568fa-37c7-11ed-aac2-506b8dbc8dfb
A302: =IFNA(VLOOKUP(D302,'Location Table'!A:C,2,false),"") -> e07c49a2-0e9a-11ee-84f9-506b8dbc8dfb | B302: =IFNA(VLOOKUP(F302,Driver!A:C,2,false),"") -> 9ba6de4c-37d0-11ed-90bb-506b8dbc8dfb | C302: =IFNA(VLOOKUP(E302,'Location Table'!A:C,2,false),"") | D302: 21362 - CChi - TL8 - PS315 Tỉnh Lộ 8 | F302: F - P - DC101161 Trần Nguyễn Thanh Duy | G302: =IFNA(VLOOKUP(F302,Driver!A:D,4,false),"") -> 1980698793628880414:XXMGIAegigeHesHcPUQpIcnMCwhigvPUATFrPyRHiqIZqTwmvWiXbUzfDhivxPcl | H302: =IFNA(VLOOKUP(F302,Driver!A:C,3,false),"") -> d0ce770b76499f17c658 | I302: 0.25 | J302: 0.64583333 | K302: 9ba6de4c-37d0-11ed-90bb-506b8dbc8dfb,987568fa-37c7-11ed-aac2-506b8dbc8dfb
A303: =IFNA(VLOOKUP(D303,'Location Table'!A:C,2,false),"") -> 56e967fc-4626-11ed-99f2-506b8dbc8dfb | B303: =IFNA(VLOOKUP(F303,Driver!A:C,2,false),"") -> c34fdbc2-ea4c-11ed-a5e2-506b8dbc8dfb | C303: =IFNA(VLOOKUP(E303,'Location Table'!A:C,2,false),"") | D303: 21362 - D11 - ACo - PS315 Âu Cơ | F303: F - P - DC101326 Trần Thanh Thái Bảo | G303: =IFNA(VLOOKUP(F303,Driver!A:D,4,false),"") -> 1980698793628880414:XXMGIAegigeHesHcPUQpIcnMCwhigvPUATFrPyRHiqIZqTwmvWiXbUzfDhivxPcl | H303: =IFNA(VLOOKUP(F303,Driver!A:C,3,false),"") -> 671c6e0f3741de1f8750 | I303: 0.29166667 | J303: 0.79166667
A304: =IFNA(VLOOKUP(D304,'Location Table'!A:C,2,false),"") -> ce820dc0-cf03-11ee-894e-506b8d9879b5 | B304: =IFNA(VLOOKUP(F304,Driver!A:C,2,false),"") -> 353f3686-dcc8-11f0-82b8-506b8d982279 | C304: =IFNA(VLOOKUP(E304,'Location Table'!A:C,2,false),"") | D304: 21362 - D11 - LTKiet - PS315 Lý Thường Kiệt | F304: F - P - DC101876 Trịnh Ngọc Sơn | G304: =IFNA(VLOOKUP(F304,Driver!A:D,4,false),"") -> 2160130926882687325:VSRHFZoYrhhtnecmAaOfmgvaKlfxBZEgxFxSbLPTAhfVwurTuJfQgOTrwyseeqJQ | H304: =IFNA(VLOOKUP(F304,Driver!A:C,3,false),"") -> e7ce6d37cc7f25217c6e | I304: 0.29166667 | J304: 0.79166667
A305: =IFNA(VLOOKUP(D305,'Location Table'!A:C,2,false),"") -> e8cd6044-4b22-11ef-902f-506b8d9879b5 | B305: =IFNA(VLOOKUP(F305,Driver!A:C,2,false),"") -> a2f538f8-37ce-11ed-a5cf-506b8dbc8dfb | C305: =IFNA(VLOOKUP(E305,'Location Table'!A:C,2,false),"") | D305: 21362 - D12 - HHGiap - PS315 Hà Huy Giáp | F305: F - C - DC100844 Nguyễn Quốc Trung | G305: =IFNA(VLOOKUP(F305,Driver!A:D,4,false),"") -> 2160130926882687325:VSRHFZoYrhhtnecmAaOfmgvaKlfxBZEgxFxSbLPTAhfVwurTuJfQgOTrwyseeqJQ | H305: =IFNA(VLOOKUP(F305,Driver!A:C,3,false),"") -> c0d10f02724a9b14c25b | I305: 0.29166667 | J305: 0.6875
A306: =IFNA(VLOOKUP(D306,'Location Table'!A:C,2,false),"") -> 702f6dc4-4626-11ed-88ba-506b8dbc8dfb | B306: =IFNA(VLOOKUP(F306,Driver!A:C,2,false),"") -> a2f538f8-37ce-11ed-a5cf-506b8dbc8dfb | C306: =IFNA(VLOOKUP(E306,'Location Table'!A:C,2,false),"") | D306: 21362 - D12 - LVKhuong - PS315 Lê Văn Khương | F306: F - C - DC100844 Nguyễn Quốc Trung | G306: =IFNA(VLOOKUP(F306,Driver!A:D,4,false),"") -> 2160130926882687325:VSRHFZoYrhhtnecmAaOfmgvaKlfxBZEgxFxSbLPTAhfVwurTuJfQgOTrwyseeqJQ | H306: =IFNA(VLOOKUP(F306,Driver!A:C,3,false),"") -> c0d10f02724a9b14c25b | I306: 0.29166667 | J306: 0.6875
A307: =IFNA(VLOOKUP(D307,'Location Table'!A:C,2,false),"") -> 542902da-21f8-11ee-bcde-506b8d9879b5 | B307: =IFNA(VLOOKUP(F307,Driver!A:C,2,false),"") -> a2f538f8-37ce-11ed-a5cf-506b8dbc8dfb | C307: =IFNA(VLOOKUP(E307,'Location Table'!A:C,2,false),"") | D307: 21362 - D12 - NAThu - PS315 Nguyễn Ảnh Thủ | F307: F - C - DC100844 Nguyễn Quốc Trung | G307: =IFNA(VLOOKUP(F307,Driver!A:D,4,false),"") -> 2160130926882687325:VSRHFZoYrhhtnecmAaOfmgvaKlfxBZEgxFxSbLPTAhfVwurTuJfQgOTrwyseeqJQ | H307: =IFNA(VLOOKUP(F307,Driver!A:C,3,false),"") -> c0d10f02724a9b14c25b | I307: 0.29166667 | J307: 0.6875
A308: =IFNA(VLOOKUP(D308,'Location Table'!A:C,2,false),"") -> 7e60488c-9b1b-11ee-8ad8-506b8d9879b5 | B308: =IFNA(VLOOKUP(F308,Driver!A:C,2,false),"") -> a2f538f8-37ce-11ed-a5cf-506b8dbc8dfb | C308: =IFNA(VLOOKUP(E308,'Location Table'!A:C,2,false),"") | D308: 21362 - D12 - NVQua - PS315 Nguyễn Văn Quá | F308: F - C - DC100844 Nguyễn Quốc Trung | G308: =IFNA(VLOOKUP(F308,Driver!A:D,4,false),"") -> 2160130926882687325:VSRHFZoYrhhtnecmAaOfmgvaKlfxBZEgxFxSbLPTAhfVwurTuJfQgOTrwyseeqJQ | H308: =IFNA(VLOOKUP(F308,Driver!A:C,3,false),"") -> c0d10f02724a9b14c25b | I308: 0.29166667 | J308: 0.6875
A309: =IFNA(VLOOKUP(D309,'Location Table'!A:C,2,false),"") -> 31419a48-09d9-11ee-8601-506b8dbc8dfb | B309: =IFNA(VLOOKUP(F309,Driver!A:C,2,false),"") -> 1d4786cc-12f7-11f1-9378-fa163ee8d8ac | C309: =IFNA(VLOOKUP(E309,'Location Table'!A:C,2,false),"") | D309: 21362 - D4 - HDieu - PS315 Hoàng Diệu | F309: F - P - DC101918 Nguyễn Bá Cường | G309: =IFNA(VLOOKUP(F309,Driver!A:D,4,false),"") -> 1980698793628880414:XXMGIAegigeHesHcPUQpIcnMCwhigvPUATFrPyRHiqIZqTwmvWiXbUzfDhivxPcl | H309: =IFNA(VLOOKUP(F309,Driver!A:C,3,false),"") -> 85d2de46a91b4045190a | I309: 0.29166667 | J309: 0.78125
A310: =IFNA(VLOOKUP(D310,'Location Table'!A:C,2,false),"") -> de879fd6-4625-11ed-94a6-506b8dbc8dfb | B310: =IFNA(VLOOKUP(F310,Driver!A:C,2,false),"") -> 51b847ba-37cd-11ed-a5f6-506b8dbc8dfb | C310: =IFNA(VLOOKUP(E310,'Location Table'!A:C,2,false),"") | D310: 21362 - D5 - THDao - PS315 Trần Hưng Đạo | F310: F - C - DC100975 Nguyễn Tấn Tài | G310: =IFNA(VLOOKUP(F310,Driver!A:D,4,false),"") -> 1980698793628880414:XXMGIAegigeHesHcPUQpIcnMCwhigvPUATFrPyRHiqIZqTwmvWiXbUzfDhivxPcl | H310: =IFNA(VLOOKUP(F310,Driver!A:C,3,false),"") -> 3d1fec9027dcce8297cd | I310: 0.29166667 | J310: 0.6875
A311: =IFNA(VLOOKUP(D311,'Location Table'!A:C,2,false),"") -> f80a7e92-4625-11ed-8ccf-506b8dbc8dfb | B311: =IFNA(VLOOKUP(F311,Driver!A:C,2,false),"") -> 061bd7aa-35a6-11ed-9426-506b8dbc8dfb | C311: =IFNA(VLOOKUP(E311,'Location Table'!A:C,2,false),"") | D311: 21362 - D6 - BPhu - PS315 Bình Phú | F311: F - P - DC100299 Đỗ Anh Quốc | G311: =IFNA(VLOOKUP(F311,Driver!A:D,4,false),"") -> 2160130926882687325:VSRHFZoYrhhtnecmAaOfmgvaKlfxBZEgxFxSbLPTAhfVwurTuJfQgOTrwyseeqJQ | H311: =IFNA(VLOOKUP(F311,Driver!A:C,3,false),"") -> a6d70e0cd7463e186757 | I311: 0.29166667 | J311: 0.66666667
A312: =IFNA(VLOOKUP(D312,'Location Table'!A:C,2,false),"") -> 0f308a76-4626-11ed-b728-506b8dbc8dfb | B312: =IFNA(VLOOKUP(F312,Driver!A:C,2,false),"") -> 65871f10-7671-11f0-9d16-506b8d982279 | C312: =IFNA(VLOOKUP(E312,'Location Table'!A:C,2,false),"") | D312: 21362 - D7 - HTPhat - PS315 Huỳnh Tấn Phát | F312: F - P - DC101616 Huỳnh Nhật Tân | G312: =IFNA(VLOOKUP(F312,Driver!A:D,4,false),"") -> 2160130926882687325:VSRHFZoYrhhtnecmAaOfmgvaKlfxBZEgxFxSbLPTAhfVwurTuJfQgOTrwyseeqJQ | H312: =IFNA(VLOOKUP(F312,Driver!A:C,3,false),"") -> 03bb8b129d5c74022d4d | I312: 0.29166667 | J312: 0.75
A313: =IFNA(VLOOKUP(D313,'Location Table'!A:C,2,false),"") -> ac6236cc-47b1-11ee-8d67-506b8d9879b5 | B313: =IFNA(VLOOKUP(F313,Driver!A:C,2,false),"") -> 9e9376b6-37c5-11ed-a1d5-506b8dbc8dfb | C313: =IFNA(VLOOKUP(E313,'Location Table'!A:C,2,false),"") | D313: 21362 - D8 - DBTrac - PS315 Dương Bá Trạc | F313: F - P - DC101469 Nguyễn Thanh Hùng | G313: =IFNA(VLOOKUP(F313,Driver!A:D,4,false),"") -> 2160130926882687325:VSRHFZoYrhhtnecmAaOfmgvaKlfxBZEgxFxSbLPTAhfVwurTuJfQgOTrwyseeqJQ | H313: =IFNA(VLOOKUP(F313,Driver!A:C,3,false),"") -> 26f3924da71c4e42170d | I313: 0.29166667 | J313: 0.75
A314: =IFNA(VLOOKUP(D314,'Location Table'!A:C,2,false),"") -> c7fafdda-21f8-11ee-b604-506b8d9879b5 | B314: =IFNA(VLOOKUP(F314,Driver!A:C,2,false),"") -> 232be490-35a4-11ed-88b7-506b8dbc8dfb | C314: =IFNA(VLOOKUP(E314,'Location Table'!A:C,2,false),"") | D314: 21362 - D9 - DXHop - PS315 Đỗ Xuân Hợp | F314: F - P - DC100734 Phan Thanh Nhật | G314: =IFNA(VLOOKUP(F314,Driver!A:D,4,false),"") -> 2160130926882687325:VSRHFZoYrhhtnecmAaOfmgvaKlfxBZEgxFxSbLPTAhfVwurTuJfQgOTrwyseeqJQ | H314: =IFNA(VLOOKUP(F314,Driver!A:C,3,false),"") -> d9fc37dd4093a9cdf082 | I314: 0.29166667 | J314: 0.6875
... A321: =IFNA(VLOOKUP(D321,'Location Table'!A:C,2,false),"") -> c828ca08-32b0-11ee-b9b6-506b8d9879b5 | B321: =IFNA(VLOOKUP(F321,Driver!A:C,2,false),"") -> a2f538f8-37ce-11ed-a5cf-506b8dbc8dfb | C321: =IFNA(VLOOKUP(E321,'Location Table'!A:C,2,false),"") | D321: 21362 - GVap - QTrung - PS315 Quang Trung | F321: F - C - DC100844 Nguyễn Quốc Trung | G321: =IFNA(VLOOKUP(F321,Driver!A:D,4,false),"") -> 2160130926882687325:VSRHFZoYrhhtnecmAaOfmgvaKlfxBZEgxFxSbLPTAhfVwurTuJfQgOTrwyseeqJQ | H321: =IFNA(VLOOKUP(F321,Driver!A:C,3,false),"") -> c0d10f02724a9b14c25b | I321: 0.29166667 | J321: 0.6875
A322: =IFNA(VLOOKUP(D322,'Location Table'!A:C,2,false),"") -> 4dba51fe-e91d-11ef-b1f0-506b8d9879b5 | B322: =IFNA(VLOOKUP(F322,Driver!A:C,2,false),"") -> 717fa61c-3654-11ed-b103-506b8dbc8dfb | C322: =IFNA(VLOOKUP(E322,'Location Table'!A:C,2,false),"") | D322: 21362 - HMon - DTVinh - PS315 Đặng Thúc Vịnh | F322: F - P - DC101166 Nguyễn Quang Trí | G322: =IFNA(VLOOKUP(F322,Driver!A:D,4,false),"") -> 1980698793628880414:XXMGIAegigeHesHcPUQpIcnMCwhigvPUATFrPyRHiqIZqTwmvWiXbUzfDhivxPcl | H322: =IFNA(VLOOKUP(F322,Driver!A:C,3,false),"") -> fbc73b7bb6385f660629 | I322: 0.23958333 | J322: 0.60416667 | K322: 717fa61c-3654-11ed-b103-506b8dbc8dfb,dff693c2-0371-11ee-90bc-506b8dbc8dfb
A323: =IFNA(VLOOKUP(D323,'Location Table'!A:C,2,false),"") -> d312de0c-4627-11ed-a9e7-506b8dbc8dfb | B323: =IFNA(VLOOKUP(F323,Driver!A:C,2,false),"") -> 717fa61c-3654-11ed-b103-506b8dbc8dfb | C323: =IFNA(VLOOKUP(E323,'Location Table'!A:C,2,false),"") | D323: 21362 - HMon - LTHa - PS315 Lê Thị Hà | F323: F - P - DC101166 Nguyễn Quang Trí | G323: =IFNA(VLOOKUP(F323,Driver!A:D,4,false),"") -> 1980698793628880414:XXMGIAegigeHesHcPUQpIcnMCwhigvPUATFrPyRHiqIZqTwmvWiXbUzfDhivxPcl | H323: =IFNA(VLOOKUP(F323,Driver!A:C,3,false),"") -> fbc73b7bb6385f660629 | I323: 0.23958333 | J323: 0.60416667 | K323: 717fa61c-3654-11ed-b103-506b8dbc8dfb,dff693c2-0371-11ee-90bc-506b8dbc8dfb
A324: =IFNA(VLOOKUP(D324,'Location Table'!A:C,2,false),"") -> ed4ce56e-d619-11ee-bf30-506b8d9879b5 | B324: =IFNA(VLOOKUP(F324,Driver!A:C,2,false),"") -> dff693c2-0371-11ee-90bc-506b8dbc8dfb | C324: =IFNA(VLOOKUP(E324,'Location Table'!A:C,2,false),"") | D324: 21362 - HMon - PVHon - PS315 Phan Văn Hớn | F324: F - P - DC101406 Bùi Hiền Anh Kiệt | G324: =IFNA(VLOOKUP(F324,Driver!A:D,4,false),"") -> 2160130926882687325:VSRHFZoYrhhtnecmAaOfmgvaKlfxBZEgxFxSbLPTAhfVwurTuJfQgOTrwyseeqJQ | H324: =IFNA(VLOOKUP(F324,Driver!A:C,3,false),"") -> 402ca9dc1194f8caa185 | I324: 0.23958333 | J324: 0.60416667 | K324: 717fa61c-3654-11ed-b103-506b8dbc8dfb,dff693c2-0371-11ee-90bc-506b8dbc8dfb
A325: =IFNA(VLOOKUP(D325,'Location Table'!A:C,2,false),"") -> 6a2f822a-f578-11ef-a059-506b8d9879b5 | B325: =IFNA(VLOOKUP(F325,Driver!A:C,2,false),"") -> 65871f10-7671-11f0-9d16-506b8d982279 | C325: =IFNA(VLOOKUP(E325,'Location Table'!A:C,2,false),"") | D325: 21362 - NBe - HTPhat - PS315 Huỳnh Tấn Phát | F325: F - P - DC101616 Huỳnh Nhật Tân | G325: =IFNA(VLOOKUP(F325,Driver!A:D,4,false),"") -> 2160130926882687325:VSRHFZoYrhhtnecmAaOfmgvaKlfxBZEgxFxSbLPTAhfVwurTuJfQgOTrwyseeqJQ | H325: =IFNA(VLOOKUP(F325,Driver!A:C,3,false),"") -> 03bb8b129d5c74022d4d | I325: 0.29166667 | J325: 0.75
A326: =IFNA(VLOOKUP(D326,'Location Table'!A:C,2,false),"") -> 3bc054d0-4627-11ed-9e74-506b8dbc8dfb | B326: =IFNA(VLOOKUP(F326,Driver!A:C,2,false),"") -> e3970cec-503e-11f1-9378-fa163ee8d8ac | C326: =IFNA(VLOOKUP(E326,'Location Table'!A:C,2,false),"") | D326: 21362 - PNhuan - PDLuu - PS315 Phan Đăng Lưu | F326: F - C - DC100017 Khưu Tấn Tài | G326: =IFNA(VLOOKUP(F326,Driver!A:D,4,false),"") | H326: =IFNA(VLOOKUP(F326,Driver!A:C,3,false),"") | I326: 0.29166667 | J326: 0.58333333
A327: =IFNA(VLOOKUP(D327,'Location Table'!A:C,2,false),"") -> a1be066c-21f8-11ee-b5fb-506b8d9879b5 | B327: =IFNA(VLOOKUP(F327,Driver!A:C,2,false),"") -> d2c2d39e-11e4-11f1-9378-fa163ee8d8ac | C327: =IFNA(VLOOKUP(E327,'Location Table'!A:C,2,false),"") | D327: 21362 - TBinh - BCat - PS315 Bàu Cát | F327: F - C - DC101924 Nguyễn Tấn Duy | G327: =IFNA(VLOOKUP(F327,Driver!A:D,4,false),"") -> 1980698793628880414:XXMGIAegigeHesHcPUQpIcnMCwhigvPUATFrPyRHiqIZqTwmvWiXbUzfDhivxPcl | H327: =IFNA(VLOOKUP(F327,Driver!A:C,3,false),"") -> 59a2bfce5a81b3dfea90 | I327: 0.29166667 | J327: 0.6875
A328: =IFNA(VLOOKUP(D328,'Location Table'!A:C,2,false),"") -> 1b89cbc6-4d4f-11ee-9f11-506b8d9879b5 | B328: =IFNA(VLOOKUP(F328,Driver!A:C,2,false),"") -> d2c2d39e-11e4-11f1-9378-fa163ee8d8ac | C328: =IFNA(VLOOKUP(E328,'Location Table'!A:C,2,false),"") | D328: 21362 - TBinh - CMT8 - PS315 CMT8 | F328: F - C - DC101924 Nguyễn Tấn Duy | G328: =IFNA(VLOOKUP(F328,Driver!A:D,4,false),"") -> 1980698793628880414:XXMGIAegigeHesHcPUQpIcnMCwhigvPUATFrPyRHiqIZqTwmvWiXbUzfDhivxPcl | H328: =IFNA(VLOOKUP(F328,Driver!A:C,3,false),"") -> 59a2bfce5a81b3dfea90 | I328: 0.29166667 | J328: 0.6875
A329: =IFNA(VLOOKUP(D329,'Location Table'!A:C,2,false),"") -> d538c282-3761-11ef-92b6-506b8d9879b5 | B329: =IFNA(VLOOKUP(F329,Driver!A:C,2,false),"") -> d2c2d39e-11e4-11f1-9378-fa163ee8d8ac | C329: =IFNA(VLOOKUP(E329,'Location Table'!A:C,2,false),"") | D329: 21362 - TBinh - HVThu - PS315 Hoàng Văn Thụ | F329: F - C - DC101924 Nguyễn Tấn Duy | G329: =IFNA(VLOOKUP(F329,Driver!A:D,4,false),"") -> 1980698793628880414:XXMGIAegigeHesHcPUQpIcnMCwhigvPUATFrPyRHiqIZqTwmvWiXbUzfDhivxPcl | H329: =IFNA(VLOOKUP(F329,Driver!A:C,3,false),"") -> 59a2bfce5a81b3dfea90 | I329: 0.29166667 | J329: 0.6875
A330: =IFNA(VLOOKUP(D330,'Location Table'!A:C,2,false),"") -> d04814d6-dc2f-11ee-96ca-506b8d9879b5 | B330: =IFNA(VLOOKUP(F330,Driver!A:C,2,false),"") -> d2c2d39e-11e4-11f1-9378-fa163ee8d8ac | C330: =IFNA(VLOOKUP(E330,'Location Table'!A:C,2,false),"") | D330: 21362 - TBinh - LLQuan - PS315 Lạc Long Quân | F330: F - C - DC101924 Nguyễn Tấn Duy | G330: =IFNA(VLOOKUP(F330,Driver!A:D,4,false),"") -> 1980698793628880414:XXMGIAegigeHesHcPUQpIcnMCwhigvPUATFrPyRHiqIZqTwmvWiXbUzfDhivxPcl | H330: =IFNA(VLOOKUP(F330,Driver!A:C,3,false),"") -> 59a2bfce5a81b3dfea90 | I330: 0.29166667 | J330: 0.6875
...

Sheet 3PL
A1: psc-tinh | B1: 3pl | C1: 3pl_uuid | D1: address
A2: BRA - D023 | B2: 3PL - HOM1 - Q1 | C2: =IFNA(VLOOKUP(B2,'Location Table'!A:C,2,false),"") -> dde21b8c-446e-11ed-bbd7-506b8dbc8dfb | D2: =IFNA(VLOOKUP(B2,'Location Table'!A:C,3,false),"") -> Bến xe Hoa Mai, 93 Nguyễn Thái Bình, Phường Nguyễn Thái Bình, Quận 1, Thành phố Hồ Chí Minh
A3: BRA - D023 | B3: 3PL - HOM2 - Q5 | C3: =IFNA(VLOOKUP(B3,'Location Table'!A:C,2,false),"") -> a4773c76-1cdc-11f0-9c7f-506b8d982279 | D3: =IFNA(VLOOKUP(B3,'Location Table'!A:C,3,false),"") -> Bến xe Hoa Mai, 275 Đ. Hùng Vương, Phường 9, Quận 5, Hồ Chí Minh
A4: BRA - D023 | B4: 3PL - TOT1 - Q1 | C4: =IFNA(VLOOKUP(B4,'Location Table'!A:C,2,false),"") -> 0d9b0456-446f-11ed-863f-506b8dbc8dfb | D4: =IFNA(VLOOKUP(B4,'Location Table'!A:C,3,false),"") -> Bến xe Toàn Thắng 21 Nguyễn Thái Bình, Phường Nguyễn Thái Bình, Bến Thành, Hồ Chí Minh
A5: BRA - D023 | B5: 3PL - TOT3 - Q5 | C5: =IFNA(VLOOKUP(B5,'Location Table'!A:C,2,false),"") -> af520b90-1736-11f0-8c50-506b8d982279 | D5: =IFNA(VLOOKUP(B5,'Location Table'!A:C,3,false),"") -> Bến xe Toàn Thắng 312 Trần Phú, Phường 7, Quận 5, Hồ Chí Minh
A6: BRA - D021 | B6: 3PL - TLT | C6: =IFNA(VLOOKUP(B6,'Location Table'!A:C,2,false),"") -> 3082e5f8-5eb6-11ee-9a38-506b8d9879b5 | D6: =IFNA(VLOOKUP(B6,'Location Table'!A:C,3,false),"") -> Bến xe Tân Lập Thành 84 Hùng Vương, Phường 9, Quận 5, Thành phố Hồ Chí Minh
A7: BRA - D030 | B7: 3PL - THB | C7: =IFNA(VLOOKUP(B7,'Location Table'!A:C,2,false),"") -> e9fca07c-446e-11ed-bd02-506b8dbc8dfb | D7: =IFNA(VLOOKUP(B7,'Location Table'!A:C,3,false),"") -> Bến xe Thành Bưởi 266 Lê Hồng Phong, Phường 4, Quận 5, Thành phố Hồ Chí Minh
A8: BRA - D036 | B8: 3PL - TLT | C8: =IFNA(VLOOKUP(B8,'Location Table'!A:C,2,false),"") -> 3082e5f8-5eb6-11ee-9a38-506b8d9879b5 | D8: =IFNA(VLOOKUP(B8,'Location Table'!A:C,3,false),"") -> Bến xe Tân Lập Thành 84 Hùng Vương, Phường 9, Quận 5, Thành phố Hồ Chí Minh
C9: =IFNA(VLOOKUP(B9,'Location Table'!A:C,2,false),"") | D9: =IFNA(VLOOKUP(B9,'Location Table'!A:C,3,false),"")
C10: =IFNA(VLOOKUP(B10,'Location Table'!A:C,2,false),"") | D10: =IFNA(VLOOKUP(B10,'Location Table'!A:C,3,false),"")
C11: =IFNA(VLOOKUP(B11,'Location Table'!A:C,2,false),"") | D11: =IFNA(VLOOKUP(B11,'Location Table'!A:C,3,false),"")
C12: =IFNA(VLOOKUP(B12,'Location Table'!A:C,2,false),"") | D12: =IFNA(VLOOKUP(B12,'Location Table'!A:C,3,false),"")

Sheet config_sun
A1: customer_id | B1: driver_id | C1: alt_drop_off_id | D1: Điểm Pick-up | E1: Điểm Drop-off thay thế | F1: Driver | G1: bot_token | H1: chat_id | I1: shift_start | J1: shift_end
A2: d4fa76f4-b95a-11f0-be92-506b8d982279 | B2: =IFNA(VLOOKUP(F2,Driver!A:C,2,false),"") -> 8094d712-0f78-11f0-b96d-506b8d982279 | C2: =IFNA(VLOOKUP(E2,'Location Table'!A:C,2,false),"") | D2: 10000 - D10 - CMT8 - Test Julie | F2: Nguyễn Thành Long | G2: 1980698793628880414:XXMGIAegigeHesHcPUQpIcnMCwhigvPUATFrPyRHiqIZqTwmvWiXbUzfDhivxPcl | H2: =IFNA(VLOOKUP(F2,Driver!A:C,3,false),"") | I2: 0.29166667 | J2: 0.66666667
A3: =IFNA(VLOOKUP(D3,'Location Table'!A:C,2,false),"") -> 7fefc6d4-4539-11ed-94b3-506b8dbc8dfb | B3: =IFNA(VLOOKUP(F3,Driver!A:C,2,false),"") -> 7898dd6c-816d-11f0-9f34-506b8d982279 | C3: =IFNA(VLOOKUP(E3,'Location Table'!A:C,2,false),"") | D3: 10232 - BHoa - VTSau - PKĐK Tâm An | F3: F - P - DC101785 Nguyễn Quốc Cường | G3: 1980698793628880414:XXMGIAegigeHesHcPUQpIcnMCwhigvPUATFrPyRHiqIZqTwmvWiXbUzfDhivxPcl | H3: =IFNA(VLOOKUP(F3,Driver!A:C,3,false),"") -> 011b70c8f4801dde4491 | I3: 0.29166667 | J3: 0.66666667
A4: =IFNA(VLOOKUP(D4,'Location Table'!A:C,2,false),"") -> 84d326dc-4543-11ed-a50a-506b8dbc8dfb | B4: =IFNA(VLOOKUP(F4,Driver!A:C,2,false),"") -> 7898dd6c-816d-11f0-9f34-506b8d982279 | C4: =IFNA(VLOOKUP(E4,'Location Table'!A:C,2,false),"") | D4: 10281 - BHoa - DVTron - Kien Clinic | F4: F - P - DC101785 Nguyễn Quốc Cường | G4: 1980698793628880414:XXMGIAegigeHesHcPUQpIcnMCwhigvPUATFrPyRHiqIZqTwmvWiXbUzfDhivxPcl | H4: =IFNA(VLOOKUP(F4,Driver!A:C,3,false),"") -> 011b70c8f4801dde4491 | I4: 0.29166667 | J4: 0.66666667
A5: =IFNA(VLOOKUP(D5,'Location Table'!A:C,2,false),"") -> 6e14d1d4-11de-11ef-9e30-506b8d9879b5 | B5: =IFNA(VLOOKUP(F5,Driver!A:C,2,false),"") -> 7898dd6c-816d-11f0-9f34-506b8d982279 | C5: =IFNA(VLOOKUP(E5,'Location Table'!A:C,2,false),"") | D5: 10304 - BHoa - 30/4 - Nguyễn Trần Tố Nữ Yến Nhi | F5: F - P - DC101785 Nguyễn Quốc Cường | G5: 1980698793628880414:XXMGIAegigeHesHcPUQpIcnMCwhigvPUATFrPyRHiqIZqTwmvWiXbUzfDhivxPcl | H5: =IFNA(VLOOKUP(F5,Driver!A:C,3,false),"") -> 011b70c8f4801dde4491 | I5: 0.29166667 | J5: 0.66666667
A6: =IFNA(VLOOKUP(D6,'Location Table'!A:C,2,false),"") -> 61af27cc-8aad-11ee-b551-506b8d9879b5 | B6: =IFNA(VLOOKUP(F6,Driver!A:C,2,false),"") -> 7898dd6c-816d-11f0-9f34-506b8d982279 | C6: =IFNA(VLOOKUP(E6,'Location Table'!A:C,2,false),"") | D6: 10323 - BHoa - DKhoi - Phạm Thị Thu Thảo | F6: F - P - DC101785 Nguyễn Quốc Cường | G6: 1980698793628880414:XXMGIAegigeHesHcPUQpIcnMCwhigvPUATFrPyRHiqIZqTwmvWiXbUzfDhivxPcl | H6: =IFNA(VLOOKUP(F6,Driver!A:C,3,false),"") -> 011b70c8f4801dde4491 | I6: 0.29166667 | J6: 0.66666667
A7: =IFNA(VLOOKUP(D7,'Location Table'!A:C,2,false),"") -> 41126efc-4349-11ef-8430-506b8d9879b5 | B7: =IFNA(VLOOKUP(F7,Driver!A:C,2,false),"") -> 7898dd6c-816d-11f0-9f34-506b8d982279 | C7: =IFNA(VLOOKUP(E7,'Location Table'!A:C,2,false),"") | D7: 10405 - BHoa - VTSau - Trần Viết Hợi | F7: F - P - DC101785 Nguyễn Quốc Cường | G7: 1980698793628880414:XXMGIAegigeHesHcPUQpIcnMCwhigvPUATFrPyRHiqIZqTwmvWiXbUzfDhivxPcl | H7: =IFNA(VLOOKUP(F7,Driver!A:C,3,false),"") -> 011b70c8f4801dde4491 | I7: 0.29166667 | J7: 0.66666667
A8: =IFNA(VLOOKUP(D8,'Location Table'!A:C,2,false),"") -> 4f07dccc-9ce9-11f0-99fb-506b8d982279 | B8: =IFNA(VLOOKUP(F8,Driver!A:C,2,false),"") -> 7898dd6c-816d-11f0-9f34-506b8d982279 | C8: =IFNA(VLOOKUP(E8,'Location Table'!A:C,2,false),"") | D8: 10877 - BHoa - NAQuoc - Nguyễn Thị Anh Ngân | F8: F - P - DC101785 Nguyễn Quốc Cường | G8: 1980698793628880414:XXMGIAegigeHesHcPUQpIcnMCwhigvPUATFrPyRHiqIZqTwmvWiXbUzfDhivxPcl | H8: =IFNA(VLOOKUP(F8,Driver!A:C,3,false),"") -> 011b70c8f4801dde4491 | I8: 0.29166667 | J8: 0.66666667
A9: =IFNA(VLOOKUP(D9,'Location Table'!A:C,2,false),"") -> f036056c-8a92-11ee-b9a1-506b8d9879b5 | B9: =IFNA(VLOOKUP(F9,Driver!A:C,2,false),"") -> 7898dd6c-816d-11f0-9f34-506b8d982279 | C9: =IFNA(VLOOKUP(E9,'Location Table'!A:C,2,false),"") | D9: 11628 - BHoa - DKhoi - Nguyễn Thị Hoàng Yến | F9: F - P - DC101785 Nguyễn Quốc Cường | G9: 1980698793628880414:XXMGIAegigeHesHcPUQpIcnMCwhigvPUATFrPyRHiqIZqTwmvWiXbUzfDhivxPcl | H9: =IFNA(VLOOKUP(F9,Driver!A:C,3,false),"") -> 011b70c8f4801dde4491 | I9: 0.29166667 | J9: 0.66666667
A10: =IFNA(VLOOKUP(D10,'Location Table'!A:C,2,false),"") -> 230eb4e2-a57d-11ef-a7db-506b8d9879b5 | B10: =IFNA(VLOOKUP(F10,Driver!A:C,2,false),"") -> 7898dd6c-816d-11f0-9f34-506b8d982279 | C10: =IFNA(VLOOKUP(E10,'Location Table'!A:C,2,false),"") | D10: 11704 - BHoa - DKhoi - Đồng Khắc Sơn | F10: F - P - DC101785 Nguyễn Quốc Cường | G10: 1980698793628880414:XXMGIAegigeHesHcPUQpIcnMCwhigvPUATFrPyRHiqIZqTwmvWiXbUzfDhivxPcl | H10: =IFNA(VLOOKUP(F10,Driver!A:C,3,false),"") -> 011b70c8f4801dde4491 | I10: 0.29166667 | J10: 0.66666667
A11: =IFNA(VLOOKUP(D11,'Location Table'!A:C,2,false),"") -> f5c156fc-11b7-11ee-a03b-506b8dbc8dfb | B11: =IFNA(VLOOKUP(F11,Driver!A:C,2,false),"") -> 7898dd6c-816d-11f0-9f34-506b8d982279 | C11: =IFNA(VLOOKUP(E11,'Location Table'!A:C,2,false),"") | D11: 11704 - BHoa - LBinh - Đồng Khắc Sơn | F11: F - P - DC101785 Nguyễn Quốc Cường | G11: 1980698793628880414:XXMGIAegigeHesHcPUQpIcnMCwhigvPUATFrPyRHiqIZqTwmvWiXbUzfDhivxPcl | H11: =IFNA(VLOOKUP(F11,Driver!A:C,3,false),"") -> 011b70c8f4801dde4491 | I11: 0.29166667 | J11: 0.66666667
A12: =IFNA(VLOOKUP(D12,'Location Table'!A:C,2,false),"") -> 3999a980-0f35-11ef-b000-506b8d9879b5 | B12: =IFNA(VLOOKUP(F12,Driver!A:C,2,false),"") -> 7898dd6c-816d-11f0-9f34-506b8d982279 | C12: =IFNA(VLOOKUP(E12,'Location Table'!A:C,2,false),"") | D12: 11752 - BHoa - F3 - Nguyễn Kim Sơn | F12: F - P - DC101785 Nguyễn Quốc Cường | G12: 1980698793628880414:XXMGIAegigeHesHcPUQpIcnMCwhigvPUATFrPyRHiqIZqTwmvWiXbUzfDhivxPcl | H12: =IFNA(VLOOKUP(F12,Driver!A:C,3,false),"") -> 011b70c8f4801dde4491 | I12: 0.29166667 | J12: 0.66666667
A13: =IFNA(VLOOKUP(D13,'Location Table'!A:C,2,false),"") -> d6fca2e0-513f-11ee-8a83-506b8d9879b5 | B13: =IFNA(VLOOKUP(F13,Driver!A:C,2,false),"") -> 7898dd6c-816d-11f0-9f34-506b8d982279 | C13: =IFNA(VLOOKUP(E13,'Location Table'!A:C,2,false),"") | D13: 11888 - BHoa - DVTron - Quách Thị Thu Hiền | F13: F - P - DC101785 Nguyễn Quốc Cường | G13: 1980698793628880414:XXMGIAegigeHesHcPUQpIcnMCwhigvPUATFrPyRHiqIZqTwmvWiXbUzfDhivxPcl | H13: =IFNA(VLOOKUP(F13,Driver!A:C,3,false),"") -> 011b70c8f4801dde4491 | I13: 0.29166667 | J13: 0.66666667
A14: =IFNA(VLOOKUP(D14,'Location Table'!A:C,2,false),"") -> 8741aed2-0d86-11ee-bea3-506b8dbc8dfb | B14: =IFNA(VLOOKUP(F14,Driver!A:C,2,false),"") -> 7898dd6c-816d-11f0-9f34-506b8d982279 | C14: =IFNA(VLOOKUP(E14,'Location Table'!A:C,2,false),"") | D14: 11957 - BHoa - BHNghia - BS. Phan Văn Trọng | F14: F - P - DC101785 Nguyễn Quốc Cường | G14: 1980698793628880414:XXMGIAegigeHesHcPUQpIcnMCwhigvPUATFrPyRHiqIZqTwmvWiXbUzfDhivxPcl | H14: =IFNA(VLOOKUP(F14,Driver!A:C,3,false),"") -> 011b70c8f4801dde4491 | I14: 0.29166667 | J14: 0.66666667
... A562: =IFNA(VLOOKUP(D562,'Location Table'!A:C,2,false),"") -> d8610906-8140-11ee-abb7-506b8d9879b5 | B562: =IFNA(VLOOKUP(F562,Driver!A:C,2,false),"") -> feb9afca-fcce-11f0-9378-fa163ee8d8ac | C562: =IFNA(VLOOKUP(E562,'Location Table'!A:C,2,false),"") | D562: 46651876 - BTan - HHLam - ND315 Hồ Học Lãm | F562: P - P - PT101695 Nguyễn Minh Đạt | G562: 1980698793628880414:XXMGIAegigeHesHcPUQpIcnMCwhigvPUATFrPyRHiqIZqTwmvWiXbUzfDhivxPcl | H562: =IFNA(VLOOKUP(F562,Driver!A:C,3,false),"") | I562: 0.6875 | J562: 0.79166667
A563: =IFNA(VLOOKUP(D563,'Location Table'!A:C,2,false),"") -> 0d517404-4621-11ed-8c7f-506b8dbc8dfb | B563: =IFNA(VLOOKUP(F563,Driver!A:C,2,false),"") -> feb9afca-fcce-11f0-9378-fa163ee8d8ac | C563: =IFNA(VLOOKUP(E563,'Location Table'!A:C,2,false),"") -> c4f51f56-1ba8-11f1-9378-fa163ee8d8ac | D563: 46651876 - BTan - LVQuoi - ND315 Lê Văn Quới | E563: BRA - D005 | F563: P - P - PT101695 Nguyễn Minh Đạt | G563: 1980698793628880414:XXMGIAegigeHesHcPUQpIcnMCwhigvPUATFrPyRHiqIZqTwmvWiXbUzfDhivxPcl | H563: =IFNA(VLOOKUP(F563,Driver!A:C,3,false),"") | I563: 0.75 | J563: 0.79166667
A564: =IFNA(VLOOKUP(D564,'Location Table'!A:C,2,false),"") -> 8a866508-0a7d-11ee-9b14-506b8dbc8dfb | B564: =IFNA(VLOOKUP(F564,Driver!A:C,2,false),"") -> f5993946-37cf-11ed-a3fc-506b8dbc8dfb | C564: =IFNA(VLOOKUP(E564,'Location Table'!A:C,2,false),"") | D564: 46651876 - BTan - NTTu - ND315 Nguyễn Thị Tú | F564: F - C - DC100993 Nguyễn Hồng Sơn | G564: 1980698793628880414:XXMGIAegigeHesHcPUQpIcnMCwhigvPUATFrPyRHiqIZqTwmvWiXbUzfDhivxPcl | H564: =IFNA(VLOOKUP(F564,Driver!A:C,3,false),"") | I564: 0.75 | J564: 0.79166667
A565: =IFNA(VLOOKUP(D565,'Location Table'!A:C,2,false),"") -> 46bb67d6-4621-11ed-908d-506b8dbc8dfb | B565: =IFNA(VLOOKUP(F565,Driver!A:C,2,false),"") -> feb9afca-fcce-11f0-9378-fa163ee8d8ac | C565: =IFNA(VLOOKUP(E565,'Location Table'!A:C,2,false),"") | D565: 46651876 - BTan - TL10 - ND315 Tỉnh Lộ 10 | F565: P - P - PT101695 Nguyễn Minh Đạt | G565: 1980698793628880414:XXMGIAegigeHesHcPUQpIcnMCwhigvPUATFrPyRHiqIZqTwmvWiXbUzfDhivxPcl | H565: =IFNA(VLOOKUP(F565,Driver!A:C,3,false),"") | I565: 0.6875 | J565: 0.79166667
A566: =IFNA(VLOOKUP(D566,'Location Table'!A:C,2,false),"") -> 9575b00e-ba9f-11ee-86c0-506b8d9879b5 | B566: =IFNA(VLOOKUP(F566,Driver!A:C,2,false),"") -> feb9afca-fcce-11f0-9378-fa163ee8d8ac | C566: =IFNA(VLOOKUP(E566,'Location Table'!A:C,2,false),"") | D566: 46651876 - BTan - TLan - ND315 Tây Lân | F566: P - P - PT101695 Nguyễn Minh Đạt | G566: 1980698793628880414:XXMGIAegigeHesHcPUQpIcnMCwhigvPUATFrPyRHiqIZqTwmvWiXbUzfDhivxPcl | H566: =IFNA(VLOOKUP(F566,Driver!A:C,3,false),"") | I566: 0.6875 | J566: 0.79166667
A567: =IFNA(VLOOKUP(D567,'Location Table'!A:C,2,false),"") -> 31d94d60-4621-11ed-a164-506b8dbc8dfb | B567: =IFNA(VLOOKUP(F567,Driver!A:C,2,false),"") -> feb9afca-fcce-11f0-9378-fa163ee8d8ac | C567: =IFNA(VLOOKUP(E567,'Location Table'!A:C,2,false),"") | D567: 46651876 - BTan - TLua - ND315 14 Tên Lửa | F567: P - P - PT101695 Nguyễn Minh Đạt | G567: 1980698793628880414:XXMGIAegigeHesHcPUQpIcnMCwhigvPUATFrPyRHiqIZqTwmvWiXbUzfDhivxPcl | H567: =IFNA(VLOOKUP(F567,Driver!A:C,3,false),"") | I567: 0.6875 | J567: 0.79166667
A568: =IFNA(VLOOKUP(D568,'Location Table'!A:C,2,false),"") -> f9b7b020-4620-11ed-a3ea-506b8dbc8dfb | B568: =IFNA(VLOOKUP(F568,Driver!A:C,2,false),"") -> feb9afca-fcce-11f0-9378-fa163ee8d8ac | C568: =IFNA(VLOOKUP(E568,'Location Table'!A:C,2,false),"") | D568: 46651876 - BTan - TLua - ND315 294 Tên Lửa | F568: P - P - PT101695 Nguyễn Minh Đạt | G568: 1980698793628880414:XXMGIAegigeHesHcPUQpIcnMCwhigvPUATFrPyRHiqIZqTwmvWiXbUzfDhivxPcl | H568: =IFNA(VLOOKUP(F568,Driver!A:C,3,false),"") | I568: 0.6875 | J568: 0.79166667
A569: =IFNA(VLOOKUP(D569,'Location Table'!A:C,2,false),"") -> b15b569a-447e-11ed-98ce-506b8dbc8dfb | B569: =IFNA(VLOOKUP(F569,Driver!A:C,2,false),"") -> c1149922-ecea-11ef-a670-506b8d9879b5 | C569: =IFNA(VLOOKUP(E569,'Location Table'!A:C,2,false),"") | D569: 46651876 - BThanh - BDang - ND315 Bạch Đằng | F569: P - C - PT101574 Lê Hoàng Anh Duy | G569: 1980698793628880414:XXMGIAegigeHesHcPUQpIcnMCwhigvPUATFrPyRHiqIZqTwmvWiXbUzfDhivxPcl | H569: =IFNA(VLOOKUP(F569,Driver!A:C,3,false),"") | I569: 0.66666667 | J569: 0.79166667
A570: =IFNA(VLOOKUP(D570,'Location Table'!A:C,2,false),"") -> 38c9c1aa-4620-11ed-9196-506b8dbc8dfb | B570: =IFNA(VLOOKUP(F570,Driver!A:C,2,false),"") -> f61678a4-3656-11ed-9310-506b8dbc8dfb | C570: =IFNA(VLOOKUP(E570,'Location Table'!A:C,2,false),"") | D570: 46651876 - D10 - THThanh - ND315 Tô Hiến Thành | F570: F - C - DC100697 Tạ Ngọc Hiền | G570: 1980698793628880414:XXMGIAegigeHesHcPUQpIcnMCwhigvPUATFrPyRHiqIZqTwmvWiXbUzfDhivxPcl | H570: =IFNA(VLOOKUP(F570,Driver!A:C,3,false),"") -> 551b71e8ffa616f84fb7 | I570: 0.5 | J570: 0.79166667
A571: =IFNA(VLOOKUP(D571,'Location Table'!A:C,2,false),"") -> 2e371346-21f8-11ee-a792-506b8d9879b5 | B571: =IFNA(VLOOKUP(F571,Driver!A:C,2,false),"") -> feb9afca-fcce-11f0-9378-fa163ee8d8ac | C571: =IFNA(VLOOKUP(E571,'Location Table'!A:C,2,false),"") | D571: 46651876 - D11 - MPhung - ND315 Minh Phụng | F571: P - P - PT101695 Nguyễn Minh Đạt | G571: 1980698793628880414:XXMGIAegigeHesHcPUQpIcnMCwhigvPUATFrPyRHiqIZqTwmvWiXbUzfDhivxPcl | H571: =IFNA(VLOOKUP(F571,Driver!A:C,3,false),"") | I571: 0.66666667 | J571: 0.79166667
A572: =IFNA(VLOOKUP(D572,'Location Table'!A:C,2,false),"") -> 6e28b82a-8c67-11f0-9f5d-506b8d982279 | B572: =IFNA(VLOOKUP(F572,Driver!A:C,2,false),"") -> 443c5016-3017-11ee-a6b5-506b8d9879b5 | C572: =IFNA(VLOOKUP(E572,'Location Table'!A:C,2,false),"") | D572: 46651876 - D12 - DTMuoi - ND315 Dương Thị Mười | F572: P - C - PT101275 Phan Thanh Phương | G572: 1980698793628880414:XXMGIAegigeHesHcPUQpIcnMCwhigvPUATFrPyRHiqIZqTwmvWiXbUzfDhivxPcl | H572: =IFNA(VLOOKUP(F572,Driver!A:C,3,false),"") -> 430767465e0cb752ee1d | I572: 0.66666667 | J572: 0.79166667
A573: =IFNA(VLOOKUP(D573,'Location Table'!A:C,2,false),"") -> 08dc27ae-4d84-11ef-ba5f-506b8d9879b5 | B573: =IFNA(VLOOKUP(F573,Driver!A:C,2,false),"") -> 443c5016-3017-11ee-a6b5-506b8d9879b5 | C573: =IFNA(VLOOKUP(E573,'Location Table'!A:C,2,false),"") | D573: 46651876 - D12 - HHGiap - ND315 Hà Huy Giáp | F573: P - C - PT101275 Phan Thanh Phương | G573: 1980698793628880414:XXMGIAegigeHesHcPUQpIcnMCwhigvPUATFrPyRHiqIZqTwmvWiXbUzfDhivxPcl | H573: =IFNA(VLOOKUP(F573,Driver!A:C,3,false),"") -> 430767465e0cb752ee1d | I573: 0.66666667 | J573: 0.79166667
A574: =IFNA(VLOOKUP(D574,'Location Table'!A:C,2,false),"") -> c9c4cd62-4620-11ed-a198-506b8dbc8dfb | B574: =IFNA(VLOOKUP(F574,Driver!A:C,2,false),"") -> 443c5016-3017-11ee-a6b5-506b8d9879b5 | C574: =IFNA(VLOOKUP(E574,'Location Table'!A:C,2,false),"") | D574: 46651876 - D12 - LVKhuong - ND315 Lê Văn Khương | F574: P - C - PT101275 Phan Thanh Phương | G574: 1980698793628880414:XXMGIAegigeHesHcPUQpIcnMCwhigvPUATFrPyRHiqIZqTwmvWiXbUzfDhivxPcl | H574: =IFNA(VLOOKUP(F574,Driver!A:C,3,false),"") -> 430767465e0cb752ee1d | I574: 0.66666667 | J574: 0.79166667
A575: =IFNA(VLOOKUP(D575,'Location Table'!A:C,2,false),"") -> acdc38c0-4620-11ed-88dd-506b8dbc8dfb | B575: =IFNA(VLOOKUP(F575,Driver!A:C,2,false),"") -> 443c5016-3017-11ee-a6b5-506b8d9879b5 | C575: =IFNA(VLOOKUP(E575,'Location Table'!A:C,2,false),"") | D575: 46651876 - D12 - NAThu - ND315 Nguyễn Ảnh Thủ | F575: P - C - PT101275 Phan Thanh Phương | G575: 1980698793628880414:XXMGIAegigeHesHcPUQpIcnMCwhigvPUATFrPyRHiqIZqTwmvWiXbUzfDhivxPcl | H575: =IFNA(VLOOKUP(F575,Driver!A:C,3,false),"") -> 430767465e0cb752ee1d | I575: 0.66666667 | J575: 0.79166667
... A605: =IFNA(VLOOKUP(D605,'Location Table'!A:C,2,false),"") -> 724b7d56-a0ab-11ee-bfe2-506b8d9879b5 | B605: =IFNA(VLOOKUP(F605,Driver!A:C,2,false),"") -> 4e1ad614-6cdb-11ef-807b-506b8d9879b5 | C605: =IFNA(VLOOKUP(E605,'Location Table'!A:C,2,false),"") | D605: 21361 - BChanh - QL50 - TM315 QL50 | F605: F - P - DC101648 Nguyễn Tấn Phát | G605: 1980698793628880414:XXMGIAegigeHesHcPUQpIcnMCwhigvPUATFrPyRHiqIZqTwmvWiXbUzfDhivxPcl | H605: =IFNA(VLOOKUP(F605,Driver!A:C,3,false),"") -> 65a6581b624a8b14d25b | I605: 0.66666667 | J605: 0.77083333
A606: =IFNA(VLOOKUP(D606,'Location Table'!A:C,2,false),"") -> b52b729a-2449-11ee-8a70-506b8d9879b5 | B606: =IFNA(VLOOKUP(F606,Driver!A:C,2,false),"") -> feb9afca-fcce-11f0-9378-fa163ee8d8ac | C606: =IFNA(VLOOKUP(E606,'Location Table'!A:C,2,false),"") -> c4f51f56-1ba8-11f1-9378-fa163ee8d8ac | D606: 21361 - BTan - LVQuoi - LK315 Lê Văn Quới | E606: BRA - D005 | F606: P - P - PT101695 Nguyễn Minh Đạt | G606: 1980698793628880414:XXMGIAegigeHesHcPUQpIcnMCwhigvPUATFrPyRHiqIZqTwmvWiXbUzfDhivxPcl | H606: =IFNA(VLOOKUP(F606,Driver!A:C,3,false),"") | I606: 0.75 | J606: 0.79166667
A607: =IFNA(VLOOKUP(D607,'Location Table'!A:C,2,false),"") -> 74ba6576-270f-11ef-ae03-506b8d9879b5 | B607: =IFNA(VLOOKUP(F607,Driver!A:C,2,false),"") -> f61678a4-3656-11ed-9310-506b8dbc8dfb | C607: =IFNA(VLOOKUP(E607,'Location Table'!A:C,2,false),"") | D607: 21361 - D10 - THThanh - TM315 Tô Hiến Thành | F607: F - C - DC100697 Tạ Ngọc Hiền | G607: 1980698793628880414:XXMGIAegigeHesHcPUQpIcnMCwhigvPUATFrPyRHiqIZqTwmvWiXbUzfDhivxPcl | H607: =IFNA(VLOOKUP(F607,Driver!A:C,3,false),"") -> 551b71e8ffa616f84fb7 | I607: 0.5 | J607: 0.79166667
A608: =IFNA(VLOOKUP(D608,'Location Table'!A:C,2,false),"") -> a1370236-312d-11ee-9841-506b8d9879b5 | B608: =IFNA(VLOOKUP(F608,Driver!A:C,2,false),"") -> 443c5016-3017-11ee-a6b5-506b8d9879b5 | C608: =IFNA(VLOOKUP(E608,'Location Table'!A:C,2,false),"") | D608: 21361 - D12 - NAThu - LK315 Nguyễn Ảnh Thủ | F608: P - C - PT101275 Phan Thanh Phương | G608: 1980698793628880414:XXMGIAegigeHesHcPUQpIcnMCwhigvPUATFrPyRHiqIZqTwmvWiXbUzfDhivxPcl | H608: =IFNA(VLOOKUP(F608,Driver!A:C,3,false),"") -> 430767465e0cb752ee1d | I608: 0.66666667 | J608: 0.79166667
A609: =IFNA(VLOOKUP(D609,'Location Table'!A:C,2,false),"") -> 3d99ca00-54a0-11ef-92b7-506b8d9879b5 | B609: =IFNA(VLOOKUP(F609,Driver!A:C,2,false),"") -> 443c5016-3017-11ee-a6b5-506b8d9879b5 | C609: =IFNA(VLOOKUP(E609,'Location Table'!A:C,2,false),"") | D609: 21361 - D12 - NVQua - TM315 Nguyễn Văn Quá | F609: P - C - PT101275 Phan Thanh Phương | G609: 1980698793628880414:XXMGIAegigeHesHcPUQpIcnMCwhigvPUATFrPyRHiqIZqTwmvWiXbUzfDhivxPcl | H609: =IFNA(VLOOKUP(F609,Driver!A:C,3,false),"") -> 430767465e0cb752ee1d | I609: 0.66666667 | J609: 0.79166667
A610: =IFNA(VLOOKUP(D610,'Location Table'!A:C,2,false),"") -> a44407ce-7bed-11ef-b6a7-506b8d9879b5 | B610: =IFNA(VLOOKUP(F610,Driver!A:C,2,false),"") -> af57dfcc-782d-11f0-b407-506b8d982279 | C610: =IFNA(VLOOKUP(E610,'Location Table'!A:C,2,false),"") | D610: 21361 - D9 - LVViet - TM315 Lê Văn Việt | F610: P - P - PT101278 Phan Thanh Nhật | G610: 1980698793628880414:XXMGIAegigeHesHcPUQpIcnMCwhigvPUATFrPyRHiqIZqTwmvWiXbUzfDhivxPcl | H610: =IFNA(VLOOKUP(F610,Driver!A:C,3,false),"") -> d9fc37dd4093a9cdf082 | I610: 0.66666667 | J610: 0.79166667
A611: =IFNA(VLOOKUP(D611,'Location Table'!A:C,2,false),"") -> e4c438d6-27bb-11ef-b969-506b8d9879b5 | B611: =IFNA(VLOOKUP(F611,Driver!A:C,2,false),"") -> 443c5016-3017-11ee-a6b5-506b8d9879b5 | C611: =IFNA(VLOOKUP(E611,'Location Table'!A:C,2,false),"") | D611: 21361 - GVap - LDTho - TM315 Lê Đức Thọ | F611: P - C - PT101275 Phan Thanh Phương | G611: 1980698793628880414:XXMGIAegigeHesHcPUQpIcnMCwhigvPUATFrPyRHiqIZqTwmvWiXbUzfDhivxPcl | H611: =IFNA(VLOOKUP(F611,Driver!A:C,3,false),"") -> 430767465e0cb752ee1d | I611: 0.66666667 | J611: 0.79166667
A612: =IFNA(VLOOKUP(D612,'Location Table'!A:C,2,false),"") -> b615381e-a3c7-11ee-9343-506b8d9879b5 | B612: =IFNA(VLOOKUP(F612,Driver!A:C,2,false),"") -> 02d08390-37cf-11ed-865f-506b8dbc8dfb | C612: =IFNA(VLOOKUP(E612,'Location Table'!A:C,2,false),"") | D612: 21361 - HMon - PVHon - LK315 Phan Văn Hớn | F612: P - P - PT101125 Lưu Minh | G612: 1980698793628880414:XXMGIAegigeHesHcPUQpIcnMCwhigvPUATFrPyRHiqIZqTwmvWiXbUzfDhivxPcl | H612: =IFNA(VLOOKUP(F612,Driver!A:C,3,false),"") -> 7b7d76055846b118e857 | I612: 0.625 | J612: 0.79166667
A613: =IFNA(VLOOKUP(D613,'Location Table'!A:C,2,false),"") -> f88dfab6-b522-11ee-bb52-506b8d9879b5 | B613: =IFNA(VLOOKUP(F613,Driver!A:C,2,false),"") -> f61678a4-3656-11ed-9310-506b8dbc8dfb | C613: =IFNA(VLOOKUP(E613,'Location Table'!A:C,2,false),"") | D613: 20210 - D3 - VVTan - Charis Healthcare Clinic | F613: F - C - DC100697 Tạ Ngọc Hiền | G613: 1980698793628880414:XXMGIAegigeHesHcPUQpIcnMCwhigvPUATFrPyRHiqIZqTwmvWiXbUzfDhivxPcl | H613: =IFNA(VLOOKUP(F613,Driver!A:C,3,false),"") -> 551b71e8ffa616f84fb7 | I613: 0.5 | J613: 0.79166667
A614: =IFNA(VLOOKUP(D614,'Location Table'!A:C,2,false),"") -> d98568e2-c9ad-11f0-8c1e-506b8d982279 | B614: =IFNA(VLOOKUP(F614,Driver!A:C,2,false),"") -> 1f4f6cae-37cd-11ed-a84d-506b8dbc8dfb | C614: =IFNA(VLOOKUP(E614,'Location Table'!A:C,2,false),"") | D614: 23579 - D5 - PHuu - Bệnh viện Năm Anh | F614: P - P - PT101084 Châu Quốc Bảo | G614: 1980698793628880414:XXMGIAegigeHesHcPUQpIcnMCwhigvPUATFrPyRHiqIZqTwmvWiXbUzfDhivxPcl | H614: =IFNA(VLOOKUP(F614,Driver!A:C,3,false),"") -> 595aed435d09b457ed18 | I614: 0.66666667 | J614: 0.79166667
A615: =IFNA(VLOOKUP(D615,'Location Table'!A:C,2,false),"") -> e05dd2f2-befa-11f0-a698-506b8d982279 | B615: =IFNA(VLOOKUP(F615,Driver!A:C,2,false),"") -> 1f4f6cae-37cd-11ed-a84d-506b8dbc8dfb | C615: =IFNA(VLOOKUP(E615,'Location Table'!A:C,2,false),"") | D615: 23579 - D5 - LHPhong - BV Năm Anh | F615: P - P - PT101084 Châu Quốc Bảo | G615: 1980698793628880414:XXMGIAegigeHesHcPUQpIcnMCwhigvPUATFrPyRHiqIZqTwmvWiXbUzfDhivxPcl | H615: =IFNA(VLOOKUP(F615,Driver!A:C,3,false),"") -> 595aed435d09b457ed18 | I615: 0.66666667 | J615: 0.79166667
A616: =IFNA(VLOOKUP(D616,'Location Table'!A:C,2,false),"") -> 6a0525ea-669c-11ef-9bd6-506b8d9879b5 | B616: =IFNA(VLOOKUP(F616,Driver!A:C,2,false),"") -> feb9afca-fcce-11f0-9378-fa163ee8d8ac | C616: =IFNA(VLOOKUP(E616,'Location Table'!A:C,2,false),"") | D616: 46647677 - BTan - 54 - BV QUỐC ÁNH | F616: P - P - PT101695 Nguyễn Minh Đạt | G616: 1980698793628880414:XXMGIAegigeHesHcPUQpIcnMCwhigvPUATFrPyRHiqIZqTwmvWiXbUzfDhivxPcl | H616: =IFNA(VLOOKUP(F616,Driver!A:C,3,false),"") | I616: 0.66666667 | J616: 0.79166667
...

Sheet PSC
A1: psc_pickup | B1: dropoff_location | C1: pickup | D1: dropoff | E1: ref_number | F1: address | G1: lat | H1: long
A2: BRA - D001 | B2: BRA - D001 | C2: =VLOOKUP(A2,Table2[[customer_name]:[customer_id]],2,0) -> 3927b076-3af9-11ed-b939-506b8dbc8dfb | D2: =VLOOKUP(B2,Table2[[customer_name]:[customer_id]],2,0) -> 3927b076-3af9-11ed-b939-506b8dbc8dfb | E2: D001▶️D001 | F2: =VLOOKUP(A2,Table2[[customer_name]:[address_line_1]],3,0) -> Diag Laboratories, 414, 420 Đ. Cao Thắng, Phường 12, Quận 10, Thành phố Hồ Chí Minh 72510 | G2: =VLOOKUP(C2,'Location Table'!B:K,9,FALSE) -> 10.775086 | H2: =VLOOKUP(C2,'Location Table'!B:K,10,FALSE) -> 106.67271
A3: BRA - D002 | B3: BRA - D001 | C3: =VLOOKUP(A3,Table2[[customer_name]:[customer_id]],2,0) -> 7bc36d6c-3d6a-11ed-a1ac-506b8dbc8dfb | D3: =VLOOKUP(B3,Table2[[customer_name]:[customer_id]],2,0) -> 3927b076-3af9-11ed-b939-506b8dbc8dfb | E3: D002▶️D001 | F3: =VLOOKUP(A3,Table2[[customer_name]:[address_line_1]],3,0) -> Diag Laboratories, 309 Dương Trần Phú, Phường 3, Quận 5, Thành phố Hồ Chí Minh 72710 | G3: =VLOOKUP(C3,'Location Table'!B:K,9,FALSE) -> 10.756428 | H3: =VLOOKUP(C3,'Location Table'!B:K,10,FALSE) -> 106.6734
A4: BRA - D003 | B4: BRA - D001 | C4: =VLOOKUP(A4,Table2[[customer_name]:[customer_id]],2,0) -> 557ec732-3af9-11ed-b159-506b8dbc8dfb | D4: =VLOOKUP(B4,Table2[[customer_name]:[customer_id]],2,0) -> 3927b076-3af9-11ed-b939-506b8dbc8dfb | E4: D003▶️D001 | F4: =VLOOKUP(A4,Table2[[customer_name]:[address_line_1]],3,0) -> Diag Laboratories, 231 Hoàng Văn Thụ, Phường 8, Phú Nhuận, Thành phố Hồ Chí Minh 72217 | G4: =VLOOKUP(C4,'Location Table'!B:K,9,FALSE) -> 10.799748 | H4: =VLOOKUP(C4,'Location Table'!B:K,10,FALSE) -> 106.6696
A5: BRA - D004 | B5: BRA - D001 | C5: =VLOOKUP(A5,Table2[[customer_name]:[customer_id]],2,0) -> 1c89cd22-3d6b-11ed-b2d6-506b8dbc8dfb | D5: =VLOOKUP(B5,Table2[[customer_name]:[customer_id]],2,0) -> 3927b076-3af9-11ed-b939-506b8dbc8dfb | E5: D004▶️D001 | F5: =VLOOKUP(A5,Table2[[customer_name]:[address_line_1]],3,0) -> Diag Laboratories, 75 Đ. Lê Văn Việt, Hiệp Phú, Quận 9, Thành phố Hồ Chí Minh | G5: =VLOOKUP(C5,'Location Table'!B:K,9,FALSE) -> 10.84737 | H5: =VLOOKUP(C5,'Location Table'!B:K,10,FALSE) -> 106.77657
A6: BRA - D005 | B6: BRA - D001 | C6: =VLOOKUP(A6,Table2[[customer_name]:[customer_id]],2,0) -> c4f51f56-1ba8-11f1-9378-fa163ee8d8ac | D6: =VLOOKUP(B6,Table2[[customer_name]:[customer_id]],2,0) -> 3927b076-3af9-11ed-b939-506b8dbc8dfb | E6: D005▶️D001 | F6: =VLOOKUP(A6,Table2[[customer_name]:[address_line_1]],3,0) -> 99 Đ. Bình Thới, Phường 11, Quận 11, Thành phố Hồ Chí Minh 72620 | G6: =VLOOKUP(C6,'Location Table'!B:K,9,FALSE) -> 10.767069 | H6: =VLOOKUP(C6,'Location Table'!B:K,10,FALSE) -> 106.64929
A7: BRA - D006 | B7: BRA - D001 | C7: =VLOOKUP(A7,Table2[[customer_name]:[customer_id]],2,0) -> c07bc96a-3d81-11ed-989f-506b8dbc8dfb | D7: =VLOOKUP(B7,Table2[[customer_name]:[customer_id]],2,0) -> 3927b076-3af9-11ed-b939-506b8dbc8dfb | E7: D006▶️D001 | F7: =VLOOKUP(A7,Table2[[customer_name]:[address_line_1]],3,0) -> Diag Laboratories, 198 Nguyễn Thị Thập, Bình Thuận, Quận 7, Thành phố Hồ Chí Minh 72914 | G7: =VLOOKUP(C7,'Location Table'!B:K,9,FALSE) -> 10.73842 | H7: =VLOOKUP(C7,'Location Table'!B:K,10,FALSE) -> 106.71641
A8: BRA - D007 | B8: BRA - D001 | C8: =VLOOKUP(A8,Table2[[customer_name]:[customer_id]],2,0) -> debfa9a0-3d81-11ed-9ba7-506b8dbc8dfb | D8: =VLOOKUP(B8,Table2[[customer_name]:[customer_id]],2,0) -> 3927b076-3af9-11ed-b939-506b8dbc8dfb | E8: D007▶️D001 | F8: =VLOOKUP(A8,Table2[[customer_name]:[address_line_1]],3,0) -> 275 Tô Ngọc Vân, Linh Đông, Thủ Đức, Thành phố Hồ Chí Minh | G8: =VLOOKUP(C8,'Location Table'!B:K,9,FALSE) -> 10.858457 | H8: =VLOOKUP(C8,'Location Table'!B:K,10,FALSE) -> 106.74875
A9: BRA - D009 | B9: BRA - D001 | C9: =VLOOKUP(A9,Table2[[customer_name]:[customer_id]],2,0) -> 7e6eb83c-3d83-11ed-b414-506b8dbc8dfb | D9: =VLOOKUP(B9,Table2[[customer_name]:[customer_id]],2,0) -> 3927b076-3af9-11ed-b939-506b8dbc8dfb | E9: D009▶️D001 | F9: =VLOOKUP(A9,Table2[[customer_name]:[address_line_1]],3,0) -> 7 Phan Văn Hớn, Tân Thới Nhất, Quận 12, Thành phố Hồ Chí Minh | G9: =VLOOKUP(C9,'Location Table'!B:K,9,FALSE) -> 10.827208 | H9: =VLOOKUP(C9,'Location Table'!B:K,10,FALSE) -> 106.62474
A10: BRA - D010 | B10: BRA - D001 | C10: =VLOOKUP(A10,Table2[[customer_name]:[customer_id]],2,0) -> 9a15e7a4-3d83-11ed-be4e-506b8dbc8dfb | D10: =VLOOKUP(B10,Table2[[customer_name]:[customer_id]],2,0) -> 3927b076-3af9-11ed-b939-506b8dbc8dfb | E10: D010▶️D001 | F10: =VLOOKUP(A10,Table2[[customer_name]:[address_line_1]],3,0) -> Trung Tâm Y Khoa Diag - Tên Lửa, 101 103 Đ. Tên Lửa, Bình Trị Đông B, Bình Tân, Thành phố Hồ Chí Minh 71908 | G10: =VLOOKUP(C10,'Location Table'!B:K,9,FALSE) -> 10.746023 | H10: =VLOOKUP(C10,'Location Table'!B:K,10,FALSE) -> 106.61232
A11: BRA - D011 | B11: BRA - D001 | C11: =VLOOKUP(A11,Table2[[customer_name]:[customer_id]],2,0) -> bbdd2320-3d83-11ed-a15b-506b8dbc8dfb | D11: =VLOOKUP(B11,Table2[[customer_name]:[customer_id]],2,0) -> 3927b076-3af9-11ed-b939-506b8dbc8dfb | E11: D011▶️D001 | F11: =VLOOKUP(A11,Table2[[customer_name]:[address_line_1]],3,0) -> 742 Lũy Bán Bích, Tân Thành, Tân Phú, Thành phố Hồ Chí Minh | G11: =VLOOKUP(C11,'Location Table'!B:K,9,FALSE) -> 10.794347 | H11: =VLOOKUP(C11,'Location Table'!B:K,10,FALSE) -> 106.63817
A12: BRA - D014 | B12: BRA - D007 | C12: =VLOOKUP(A12,Table2[[customer_name]:[customer_id]],2,0) -> c79d5fa2-3d85-11ed-a6db-506b8dbc8dfb | D12: =VLOOKUP(B12,Table2[[customer_name]:[customer_id]],2,0) -> debfa9a0-3d81-11ed-9ba7-506b8dbc8dfb | E12: D014▶️D007 | F12: =VLOOKUP(A12,Table2[[customer_name]:[address_line_1]],3,0) -> Diag Laboratories, 495 Đ. Cách Mạng Tháng 8, Phú Cường, Thủ Dầu Một, Bình Dương 75153 | G12: =VLOOKUP(C12,'Location Table'!B:K,9,FALSE) -> 10.979216 | H12: =VLOOKUP(C12,'Location Table'!B:K,10,FALSE) -> 106.65549
A13: BRA - D015 | B13: BRA - D004 | C13: =VLOOKUP(A13,Table2[[customer_name]:[customer_id]],2,0) -> 0c0b1998-3d88-11ed-8d9a-506b8dbc8dfb | D13: =VLOOKUP(B13,Table2[[customer_name]:[customer_id]],2,0) -> 1c89cd22-3d6b-11ed-b2d6-506b8dbc8dfb | E13: D015▶️D004 | F13: =VLOOKUP(A13,Table2[[customer_name]:[address_line_1]],3,0) -> Diag Laboratories, 139 - 141 (số cũ, 241 Đ. Võ Thị Sáu, Khu Phố 7, Tp. Biên Hòa, Đồng Nai 76108 | G13: =VLOOKUP(C13,'Location Table'!B:K,9,FALSE) -> 10.947309 | H13: =VLOOKUP(C13,'Location Table'!B:K,10,FALSE) -> 106.82841
... A25: BRA - D029 | B25: BRA - D001 | C25: =VLOOKUP(A25,Table2[[customer_name]:[customer_id]],2,0) -> c81985d4-3d9c-11ed-8951-506b8dbc8dfb | D25: =VLOOKUP(B25,Table2[[customer_name]:[customer_id]],2,0) -> 3927b076-3af9-11ed-b939-506b8dbc8dfb | E25: D029▶️D001 | F25: =VLOOKUP(A25,Table2[[customer_name]:[address_line_1]],3,0) -> Diag Laboratories, 101 Đ. Đinh Tiên Hoàng, Đa Kao, Quận 1, Thành phố Hồ Chí Minh 71007 | G25: =VLOOKUP(C25,'Location Table'!B:K,9,FALSE) -> 10.79036 | H25: =VLOOKUP(C25,'Location Table'!B:K,10,FALSE) -> 106.69733
A26: BRA - D030 | B26: 3PL - D030 - THB | C26: =VLOOKUP(A26,Table2[[customer_name]:[customer_id]],2,0) -> c450f244-3b21-11f1-9378-fa163ee8d8ac | D26: =VLOOKUP(B26,Table2[[customer_name]:[customer_id]],2,0) -> b959ed68-446d-11ed-b04f-506b8dbc8dfb | F26: =VLOOKUP(A26,Table2[[customer_name]:[address_line_1]],3,0) -> 54Z1B, Đ. Trần Nam Phú, Khu vực 2, Tân An, Cần Thơ | G26: =VLOOKUP(C26,'Location Table'!B:K,9,FALSE) -> 10.033813 | H26: =VLOOKUP(C26,'Location Table'!B:K,10,FALSE) -> 105.76373
A27: BRA - D032 | B27: BRA - D007 | C27: =VLOOKUP(A27,Table2[[customer_name]:[customer_id]],2,0) -> 17dd37b4-3d9d-11ed-93b6-506b8dbc8dfb | D27: =VLOOKUP(B27,Table2[[customer_name]:[customer_id]],2,0) -> debfa9a0-3d81-11ed-9ba7-506b8dbc8dfb | E27: D036▶️D001 | F27: =VLOOKUP(A27,Table2[[customer_name]:[address_line_1]],3,0) -> Diag Laboratories, 67A Nguyễn Văn Tiết, Lái Thiêu, Thuận An, Bình Dương 75206 | G27: =VLOOKUP(C27,'Location Table'!B:K,9,FALSE) -> 10.90835 | H27: =VLOOKUP(C27,'Location Table'!B:K,10,FALSE) -> 106.70142
A28: BRA - D033 | B28: BRA - D009 | C28: =VLOOKUP(A28,Table2[[customer_name]:[customer_id]],2,0) -> 24b9b3d6-3d9d-11ed-b9a1-506b8dbc8dfb | D28: =VLOOKUP(B28,Table2[[customer_name]:[customer_id]],2,0) -> 7e6eb83c-3d83-11ed-b414-506b8dbc8dfb | E28: D033▶️D009 | F28: =VLOOKUP(A28,Table2[[customer_name]:[address_line_1]],3,0) -> Diag Laboratories, 31, 5 Đ. Quang Trung, TT. Hóc Môn, Hóc Môn, Thành phố Hồ Chí Minh 71706 | G28: =VLOOKUP(C28,'Location Table'!B:K,9,FALSE) -> 10.888009 | H28: =VLOOKUP(C28,'Location Table'!B:K,10,FALSE) -> 106.59853
A29: BRA - D035 | B29: BRA - D001 | C29: =VLOOKUP(A29,Table2[[customer_name]:[customer_id]],2,0) -> 77531e70-3d9d-11ed-bccd-506b8dbc8dfb | D29: =VLOOKUP(B29,Table2[[customer_name]:[customer_id]],2,0) -> 3927b076-3af9-11ed-b939-506b8dbc8dfb | E29: D035▶️D001 | F29: =VLOOKUP(A29,Table2[[customer_name]:[address_line_1]],3,0) -> Diag Laboratories, 1375, 1377 Huỳnh Tấn Phát, KP4, Quận 7, Thành phố Hồ Chí Minh 72907 | G29: =VLOOKUP(C29,'Location Table'!B:K,9,FALSE) -> 10.715441 | H29: =VLOOKUP(C29,'Location Table'!B:K,10,FALSE) -> 106.73706
A30: BRA - D036 | B30: BRA - D001 | C30: =VLOOKUP(A30,Table2[[customer_name]:[customer_id]],2,0) -> a22daf7a-3d9d-11ed-8890-506b8dbc8dfb | D30: =VLOOKUP(B30,Table2[[customer_name]:[customer_id]],2,0) -> 3927b076-3af9-11ed-b939-506b8dbc8dfb | E30: D036▶️D001 | F30: =VLOOKUP(A30,Table2[[customer_name]:[address_line_1]],3,0) -> Diag Laboratories, 129 Nguyễn Đình Chiểu, Phường 1, Tân An, Long An 82106 | G30: =VLOOKUP(C30,'Location Table'!B:K,9,FALSE) -> 10.535476 | H30: =VLOOKUP(C30,'Location Table'!B:K,10,FALSE) -> 106.41704
A31: BRA - D036 | B31: 3PL - D036 - TLT | C31: =VLOOKUP(A31,Table2[[customer_name]:[customer_id]],2,0) -> a22daf7a-3d9d-11ed-8890-506b8dbc8dfb | D31: =VLOOKUP(B31,Table2[[customer_name]:[customer_id]],2,0) -> 8350b9b4-5e65-11ee-aa4d-506b8d9879b5 | E31: D036▶️3PL | F31: =VLOOKUP(A31,Table2[[customer_name]:[address_line_1]],3,0) -> Diag Laboratories, 129 Nguyễn Đình Chiểu, Phường 1, Tân An, Long An 82106 | G31: =VLOOKUP(C31,'Location Table'!B:K,9,FALSE) -> 10.535476 | H31: =VLOOKUP(C31,'Location Table'!B:K,10,FALSE) -> 106.41704
A32: BRA - D037 | B32: BRA - D001 | C32: =VLOOKUP(A32,Table2[[customer_name]:[customer_id]],2,0) -> ec32d0d2-ceec-11ee-bad2-506b8d9879b5 | D32: =VLOOKUP(B32,Table2[[customer_name]:[customer_id]],2,0) -> 3927b076-3af9-11ed-b939-506b8dbc8dfb | E32: D037▶️D001 | F32: =VLOOKUP(A32,Table2[[customer_name]:[address_line_1]],3,0) -> 323 Đ. Nguyễn Duy Trinh, Phường Bình Trưng Tây, Quận 2, Thành phố Hồ Chí Minh | G32: =VLOOKUP(C32,'Location Table'!B:K,9,FALSE) -> 10.788097 | H32: =VLOOKUP(C32,'Location Table'!B:K,10,FALSE) -> 106.76624
A33: BRA - D038 | B33: BRA - D001 | C33: =VLOOKUP(A33,Table2[[customer_name]:[customer_id]],2,0) -> cc143b9c-ceec-11ee-9518-506b8d9879b5 | D33: =VLOOKUP(B33,Table2[[customer_name]:[customer_id]],2,0) -> 3927b076-3af9-11ed-b939-506b8dbc8dfb | E33: D038▶️D001 | F33: =VLOOKUP(A33,Table2[[customer_name]:[address_line_1]],3,0) -> 1166 Đ. Cách Mạng Tháng 8, Phường 4, Tân Bình, Thành phố Hồ Chí Minh | G33: =VLOOKUP(C33,'Location Table'!B:K,9,FALSE) -> 10.791934 | H33: =VLOOKUP(C33,'Location Table'!B:K,10,FALSE) -> 106.6555
A34: BRA - D039 | B34: BRA - D001 | C34: =VLOOKUP(A34,Table2[[customer_name]:[customer_id]],2,0) -> b188329c-ceec-11ee-bae4-506b8d9879b5 | D34: =VLOOKUP(B34,Table2[[customer_name]:[customer_id]],2,0) -> 3927b076-3af9-11ed-b939-506b8dbc8dfb | E34: D039▶️D001 | F34: =VLOOKUP(A34,Table2[[customer_name]:[address_line_1]],3,0) -> 375 Đ. Nguyễn Văn Luông, Phường 12, Quận 6, Thành phố Hồ Chí Minh | G34: =VLOOKUP(C34,'Location Table'!B:K,9,FALSE) -> 10.751132 | H34: =VLOOKUP(C34,'Location Table'!B:K,10,FALSE) -> 106.635
A35: BRA - D040 | B35: BRA - D001 | C35: =VLOOKUP(A35,Table2[[customer_name]:[customer_id]],2,0) -> af190f62-0ce6-11ef-ba8a-506b8d9879b5 | D35: =VLOOKUP(B35,Table2[[customer_name]:[customer_id]],2,0) -> 3927b076-3af9-11ed-b939-506b8dbc8dfb | E35: D040▶️D001 | F35: =VLOOKUP(A35,Table2[[customer_name]:[address_line_1]],3,0) -> 869 Đ. Phan Văn Trị, Phường 7, Gò Vấp, Thành phố Hồ Chí Minh | G35: =VLOOKUP(C35,'Location Table'!B:K,9,FALSE) -> 10.829273 | H35: =VLOOKUP(C35,'Location Table'!B:K,10,FALSE) -> 106.6816
A36: BRA - D041 | B36: BRA - D001 | C36: =VLOOKUP(A36,Table2[[customer_name]:[customer_id]],2,0) -> 21dcad6a-0ce7-11ef-af2f-506b8d9879b5 | D36: =VLOOKUP(B36,Table2[[customer_name]:[customer_id]],2,0) -> 3927b076-3af9-11ed-b939-506b8dbc8dfb | E36: D041▶️D001 | F36: =VLOOKUP(A36,Table2[[customer_name]:[address_line_1]],3,0) -> 75-77 Nguyễn Thị Tú, Bình Hưng Hoà B, Bình Tân, Thành phố Hồ Chí Minh | G36: =VLOOKUP(C36,'Location Table'!B:K,9,FALSE) -> 10.815858 | H36: =VLOOKUP(C36,'Location Table'!B:K,10,FALSE) -> 106.59852
A37: BRA - D042 | B37: BRA - D001 | C37: =VLOOKUP(A37,Table2[[customer_name]:[customer_id]],2,0) -> 37c8f934-0ce8-11ef-900c-506b8d9879b5 | D37: =VLOOKUP(B37,Table2[[customer_name]:[customer_id]],2,0) -> 3927b076-3af9-11ed-b939-506b8dbc8dfb | E37: D042▶️D001 | F37: =VLOOKUP(A37,Table2[[customer_name]:[address_line_1]],3,0) -> 1B Đường số 5, Phước Bình, Quận 9, Thành phố Hồ Chí Minh | G37: =VLOOKUP(C37,'Location Table'!B:K,9,FALSE) -> 10.81819 | H37: =VLOOKUP(C37,'Location Table'!B:K,10,FALSE) -> 106.77306
